[2025-07-01 15:35:43 UTC] Error while creating execution plan for Job
[2025-07-01 15:35:43 UTC] Traceback (most recent call last):
[2025-07-01 15:35:43 UTC]   File "/opt/corridor/venv/lib/python3.11/site-packages/fs/osfs.py", line 647, in open
[2025-07-01 15:35:43 UTC]     return io.open(
[2025-07-01 15:35:43 UTC]            ^^^^^^^^
[2025-07-01 15:35:43 UTC] FileNotFoundError: [Errno 2] No such file or directory: b'/opt/corridor/uploads/data_table_1/data/f1_20250701_134952/def.json'
[2025-07-01 15:35:43 UTC] During handling of the above exception, another exception occurred:
[2025-07-01 15:35:43 UTC] Traceback (most recent call last):
[2025-07-01 15:35:43 UTC]   File "/opt/corridor/venv/lib/python3.11/site-packages/corridor_api/tasks/simulation_task.py", line 656, in start_simulation
[2025-07-01 15:35:43 UTC]     taskdata["data"] = populate_data(dict.fromkeys(exec_datacols), sim_entity)
[2025-07-01 15:35:43 UTC]                        ^^^^^^^^^^^^^^^^^^^^^^^^^^^^^^^^^^^^^^^^^^^^^^^^^^^^^^^
[2025-07-01 15:35:43 UTC]   File "/opt/corridor/venv/lib/python3.11/site-packages/corridor_api/tasks/simulation_task.py", line 311, in populate_data
[2025-07-01 15:35:43 UTC]     "source": FileAttachmentService.readbytes(table.file),
[2025-07-01 15:35:43 UTC]               ^^^^^^^^^^^^^^^^^^^^^^^^^^^^^^^^^^^^^^^^^^^
[2025-07-01 15:35:43 UTC]   File "/opt/corridor/venv/lib/python3.11/site-packages/corridor_api/services/file_attachment_service.py", line 140, in readbytes
[2025-07-01 15:35:43 UTC]     return cls.storage.readbytes(entity.location)
[2025-07-01 15:35:43 UTC]            ^^^^^^^^^^^^^^^^^^^^^^^^^^^^^^^^^^^^^^
[2025-07-01 15:35:43 UTC]   File "/opt/corridor/venv/lib/python3.11/site-packages/fs/base.py", line 627, in readbytes
[2025-07-01 15:35:43 UTC]     with closing(self.open(path, mode="rb")) as read_file:
[2025-07-01 15:35:43 UTC]                  ^^^^^^^^^^^^^^^^^^^^^^^^^^
[2025-07-01 15:35:43 UTC]   File "/opt/corridor/venv/lib/python3.11/site-packages/fs/osfs.py", line 643, in open
[2025-07-01 15:35:43 UTC]     with convert_os_errors("open", path):
[2025-07-01 15:35:43 UTC]   File "/opt/corridor/venv/lib/python3.11/site-packages/fs/error_tools.py", line 89, in __exit__
[2025-07-01 15:35:43 UTC]     reraise(fserror, fserror(self._path, exc=exc_value), traceback)
[2025-07-01 15:35:43 UTC]   File "/opt/corridor/venv/lib/python3.11/site-packages/six.py", line 723, in reraise
[2025-07-01 15:35:43 UTC]     raise value.with_traceback(tb)
[2025-07-01 15:35:43 UTC]   File "/opt/corridor/venv/lib/python3.11/site-packages/fs/osfs.py", line 647, in open
[2025-07-01 15:35:43 UTC]     return io.open(
[2025-07-01 15:35:43 UTC]            ^^^^^^^^
[2025-07-01 15:35:43 UTC] fs.errors.ResourceNotFound: resource 'data_table_1/data/f1_20250701_134952/def.json' not found
