ERROR: UnboundLocalError: local variable 'exec_sig' referenced before assignment

Logs:
Got args: ()
Got kwargs: {'job_id': 12, 'last_task_endtime': None}
Got retval: None

Traceback:
Traceback (most recent call last):
  File "/home/rajneesh/corridor_code/corridor-api/apps/corridor-api/corridor_api/tasks/__init__.py", line 116, in __call__
    retval = super().__call__(*args, **kwargs)
  File "/home/rajneesh/corridor_code/corridor-api/apps/corridor-api/venv/lib/python3.8/site-packages/celery/app/trace.py", line 760, in __protected_call__
    return self.run(*args, **kwargs)
  File "/home/rajneesh/corridor_code/corridor-api/apps/corridor-api/corridor_api/tasks/simulation_task.py", line 864, in start_simulation
    report_task, exec_signature, exec_datacols = get_sim_exec_task(sim_entity, lang_spec=lang_spec)
  File "/home/rajneesh/corridor_code/corridor-api/apps/corridor-api/corridor_api/tasks/simulation_task.py", line 526, in get_sim_exec_task
    return report_task, exec_sig, exec_datacols
UnboundLocalError: local variable 'exec_sig' referenced before assignment

During handling of the above exception, another exception occurred:

Traceback (most recent call last):
  File "/home/rajneesh/corridor_code/corridor-api/apps/corridor-api/venv/lib/python3.8/site-packages/celery/app/trace.py", line 477, in trace_task
    R = retval = fun(*args, **kwargs)
  File "/home/rajneesh/corridor_code/corridor-api/apps/corridor-api/corridor_api/tasks/__init__.py", line 156, in __call__
    retval = super().__call__(*args, **kwargs)
  File "/home/rajneesh/corridor_code/corridor-api/apps/corridor-api/corridor_api/tasks/__init__.py", line 134, in __call__
    raise app_exc
corridor_api.exception.exceptions.TaskException: UnboundLocalError: local variable 'exec_sig' referenced before assignment
