Internal Exception:
UnboundLocalError: local variable 'app_exc' referenced before assignment

Traceback:
Traceback (most recent call last):
  File "/home/rajneesh/corridor_code/corridor-api/apps/corridor-api/corridor_api/tasks/__init__.py", line 116, in __call__
    retval = super().__call__(*args, **kwargs)
  File "/home/rajneesh/corridor_code/corridor-api/apps/corridor-api/venv/lib/python3.8/site-packages/celery/app/trace.py", line 760, in __protected_call__
    return self.run(*args, **kwargs)
  File "/home/rajneesh/corridor_code/corridor-api/apps/corridor-api/corridor_api/tasks/simulation_task.py", line 854, in start_simulation
    job = task_utils.get_running_job(job_id)
  File "/home/rajneesh/corridor_code/corridor-api/apps/corridor-api/corridor_api/util/task_utils.py", line 741, in get_running_job
    raise TaskException(message)
corridor_api.exception.exceptions.TaskException: The job with id=<ScheduledJob #10> is already executed. Halt execution

During handling of the above exception, another exception occurred:

Traceback (most recent call last):
  File "/home/rajneesh/corridor_code/corridor-api/apps/corridor-api/venv/lib/python3.8/site-packages/celery/app/trace.py", line 477, in trace_task
    R = retval = fun(*args, **kwargs)
  File "/home/rajneesh/corridor_code/corridor-api/apps/corridor-api/corridor_api/tasks/__init__.py", line 156, in __call__
    retval = super().__call__(*args, **kwargs)
  File "/home/rajneesh/corridor_code/corridor-api/apps/corridor-api/corridor_api/tasks/__init__.py", line 134, in __call__
    raise app_exc
UnboundLocalError: local variable 'app_exc' referenced before assignment
