Error occured while generating Report Output "Overall Trust Score"
---------------------------------------------------------------------------
IndexError                                Traceback (most recent call last):
 Report Output "Overall Trust Score" <v1>, line 70, in <definition>
        65 |     for i in fig["layout"]["annotations"]:
        66 |         i["font"] = dict(size=20, color="#424242")
        67 |     return fig
---->   70 | return gauge_charts(raw_output)
                    ^^^^^^^^^^^^^^^^^^^^^^^^
    Local variables:
      job           = <Job job_type="Simulati...: Jun-20-2025 02:21 PM">
      raw_output    = {'metrics_df': pandas.DataFrame[Metric: object, Score Reviewer-1: float64, Explanation Reviewer-1: object, Response Reviewer-1: object, Tags Reviewer-1: object, Mean Score: float64, common_tags: object], 'overall_readiness': 66.67, 'pointers_for_improvement': 'Based on a thorough an...iased in all scenarios.', 'tags_df': pandas.DataFrame[Metric: object, Category: object, is_fine: int64]}
 Report Output "Overall Trust Score" <v1>, line 22, in gauge_charts
        19 | row_idx = 1
        20 | col_idx = 1
        21 | for model_name, data in raw_output.items():
---->   22 |     overall_readiness = data["overall_readiness"]
                                     ^^^^^^^^^^^^^^^^^^^^^^^^^
        23 |     if overall_readiness >= 85:
    Local variables:
      raw_output    = {'metrics_df': pandas.DataFrame[Metric: object, Score Reviewer-1: float64, Explanation Reviewer-1: object, Response Reviewer-1: object, Tags Reviewer-1: object, Mean Score: float64, common_tags: object], 'overall_readiness': 66.67, 'pointers_for_improvement': 'Based on a thorough an...iased in all scenarios.', 'tags_df': pandas.DataFrame[Metric: object, Category: object, is_fine: int64]}
      num_models    = 4
      rows          = 2
      fig           = Figure({
                          'data': []...   'template': '...'}
                      })
      row_idx       = 1
      col_idx       = 1
      model_name    = 'overall_readiness'
      data          = 66.67
IndexError: invalid index to scalar variable.