[2025-09-04 15:34:34 UTC] Report execution completed. Generating outputs...
[2025-09-04 15:34:39 UTC] Error occured while generating Report Output "Average Prompt Quality Score"
[2025-09-04 15:34:39 UTC] ---------------------------------------------------------------------------
[2025-09-04 15:34:39 UTC] KeyError                                  Traceback (most recent call last):
[2025-09-04 15:34:39 UTC]  Report Figure "Average Prompt Quality Score" <v1>, line 1, in <definition>
[2025-09-04 15:34:39 UTC] ---->    1 |     score = raw_output["metrics_df"]["average_score"]
[2025-09-04 15:34:39 UTC]                          ^^^^^^^^^^^^^^^^^^^^^^^^^^^^^^^^^^^^^^^^^
[2025-09-04 15:34:39 UTC]          2 |     return f"""
[2025-09-04 15:34:39 UTC]          3 |     <!DOCTYPE html>
[2025-09-04 15:34:39 UTC]          4 |     <html lang="en">
[2025-09-04 15:34:39 UTC] (...)
[2025-09-04 15:34:39 UTC]         45 |     </html>
[2025-09-04 15:34:39 UTC]         46 |     """.format(score=raw_output["metrics_df"]["average_score"])
[2025-09-04 15:34:39 UTC]     Local variables:
[2025-09-04 15:34:39 UTC]       job           = <Job job_type="Simulati...: Sep-04-2025 09:02 PM">
[2025-09-04 15:34:39 UTC]       raw_output    = {'average_score': 4.0, 'metrics_df': pandas.DataFrame[Metric: object, Score Reviewer-1: int64, Explanation Reviewer-1: object, Response Reviewer-1: object, Tags Reviewer-1: object, Mean Score: float64, common_tags: object], 'tags_df': pandas.DataFrame[Metric: object, Category: object, is_fine: int64]}
[2025-09-04 15:34:39 UTC]  File "/opt/corridor/venv/lib/python3.11/site-packages/pandas/core/frame.py", line 3807, in DataFrame.__getitem__
[2025-09-04 15:34:39 UTC]       3804 | if is_single_key:
[2025-09-04 15:34:39 UTC]       3805 |     if self.columns.nlevels > 1:
[2025-09-04 15:34:39 UTC]       3806 |         return self._getitem_multilevel(key)
[2025-09-04 15:34:39 UTC] ----> 3807 |     indexer = self.columns.get_loc(key)
[2025-09-04 15:34:39 UTC]                            ^^^^^^^^^^^^^^^^^^^^^^^^^
[2025-09-04 15:34:39 UTC]       3808 |     if is_integer(indexer):
[2025-09-04 15:34:39 UTC]  File "/opt/corridor/venv/lib/python3.11/site-packages/pandas/core/indexes/base.py", line 3804, in Index.get_loc
[2025-09-04 15:34:39 UTC]       3801 | try:
[2025-09-04 15:34:39 UTC]       3802 |     return self._engine.get_loc(casted_key)
[2025-09-04 15:34:39 UTC]       3803 | except KeyError as err:
[2025-09-04 15:34:39 UTC] ----> 3804 |     raise KeyError(key) from err
[2025-09-04 15:34:39 UTC]       3805 | except TypeError:
[2025-09-04 15:34:39 UTC]       3806 |     # If we have a listlike key, _check_indexing_error will raise
[2025-09-04 15:34:39 UTC]       3807 |     #  InvalidIndexError. Otherwise we fall through and re-raise
[2025-09-04 15:34:39 UTC]       3808 |     #  the TypeError.
[2025-09-04 15:34:39 UTC] KeyError: 'average_score'
[2025-09-04 15:34:40 UTC] All 4 outputs and additional figures processed.
